Workbook

Sheet Variecose
A1: COMMESSA: | B1: 215_ALFONSINE
A2: OPERA D'ARTE: | B2: VIADOTTO DI APPROCCIO EST
A3: Data: | B3: 45128
A4: File Midas: | B4: 02_Alfonsine_Viadotto est
A5: File SuperFoglio: | B5: 05_Alfonsine_Viadotto_EST_SPF
D7: Spalla | L7: Pila | X7: Pila
A8: concio : | D8: 1 | F8: 2 | H8: 3 | J8: 4 | L8: 5 | N8: 6 | P8: 7 | R8: 8 | T8: 9 | V8: 10 | X8: 11
A9: Giunzione bullonata o saldata? (B/S) [hmin | hmax]= | D9: S | E9: S | F9: S | G9: S | H9: S | I9: S | J9: S | K9: S | L9: S | M9: S | N9: S | O9: S | P9: S | Q9: S | R9: S | S9: S | T9: S | U9: S | V9: S | W9: S | X9: S | Y9: S
A10: Armatura longitudinale superiore al metro trasversale [n | Φ /m] = | D10: 5 | E10: 26 | F10: 5 | G10: 20 | H10: 5 | I10: 20 | J10: 10 | K10: 26 | L10: 10 | M10: 26 | N10: 10 | O10: 26 | P10: 10 | Q10: 22 | R10: 10 | S10: 16 | T10: 10 | U10: 22 | V10: 10 | W10: 26 | X10: 10 | Y10: 26
A11: Armatura longitudinale superiore al metro trasversale [mm2/m] = | D11: 2654.6458 | F11: 1570.7963 | H11: 1570.7963 | J11: 5309.2916 | L11: 5309.2916 | N11: 5309.2916 | P11: 3801.3271 | R11: 2010.6193 | T11: 3801.3271 | V11: 5309.2916 | X11: 5309.2916
A12: Distanza dall'estradosso soletta - arm.superiore [mm] = | D12: 50 | F12: 50 | H12: 50 | J12: 50 | L12: 50 | N12: 50 | P12: 50 | R12: 50 | T12: 50 | V12: 50 | X12: 50
A13: Armatura longitudinale inferiore al metro trasversale [n | Φ /m] = | J13: 10 | K13: 26 | L13: 10 | M13: 26 | N13: 10 | O13: 26 | V13: 10 | W13: 26 | X13: 10 | Y13: 26
A14: Armatura longitudinale inferiore al metro trasversale [mm2/m] = | D14: 0 | F14: 0 | H14: 0 | J14: 5309.2916 | L14: 5309.2916 | N14: 5309.2916 | P14: 0 | R14: 0 | T14: 0 | V14: 5309.2916 | X14: 5309.2916
A15: Distanza dall'estradosso soletta - arm.inferiore [mm] = | D15: 289 | F15: 289 | H15: 289 | J15: 270 | L15: 270 | N15: 270 | P15: 289 | R15: 289 | T15: 289 | V15: 270 | X15: 270
A16: Area della diagonale inferiore di controvento [mm2] = | D16: 0 | F16: 0 | H16: 0 | J16: 0 | L16: 0 | N16: 0 | P16: 0 | R16: 0 | T16: 0 | V16: 0 | X16: 0
C17: n° di diagonali in una maglia = | D17: 0 | F17: 0 | H17: 0 | J17: 0 | L17: 0 | N17: 0 | P17: 0 | R17: 0 | T17: 0 | V17: 0 | X17: 0
A18: Larghezza soletta [mm] = | D18: 14300 | F18: 14300 | H18: 14300 | J18: 14300 | L18: 14300 | N18: 14300 | P18: 14300 | R18: 14300 | T18: 14300 | V18: 14300 | X18: 14300
A19: Sbalzo soletta lato di verifica [mm] = | D19: 2650 | F19: 2650 | H19: 2650 | J19: 2650 | L19: 2650 | N19: 2650 | P19: 2650 | R19: 2650 | T19: 2650 | V19: 2650 | X19: 2650
A20: Riduzione soletta collaborante [sbalzo | interno ] [mm] = | D20: 0 | E20: 0 | F20: 0 | G20: 0 | H20: 0 | I20: 0 | J20: 0 | K20: 0 | L20: 0 | M20: 0 | N20: 0 | O20: 0 | P20: 0 | Q20: 0 | R20: 0 | S20: 0 | T20: 0 | U20: 0 | V20: 0 | W20: 0 | X20: 0 | Y20: 0
A21: LAMIERE
C22: Rapporto limite per il web breathing | rapporto bw/tw | D22: 184 | E22: 106.8 | F22: 184 | G22: 131.625 | H22: 184 | I22: 105.3 | J22: 184 | K22: 87.5 | L22: 184 | M22: 85 | N22: 230 | O22: 86.666667 | P22: 230 | Q22: 105.3 | R22: 230 | S22: 131.625 | T22: 230 | U22: 105.6 | V22: 230 | W22: 87.5 | X22: 230 | Y22: 85
A23: concio : | D23: 1 | F23: 2 | H23: 3 | J23: 4 | L23: 5 | N23: 6 | P23: 7 | R23: 8 | T23: 9 | V23: 10 | X23: 11
A24: Lunghezza della travata [mm] = | D24: 38500 | F24: 38500 | H24: 38500 | J24: 38500 | L24: 38500 | N24: 50000 | P24: 50000 | R24: 50000 | T24: 50000 | V24: 50000 | X24: 50000
A25: Interasse superiore fra le travi [hmin | hmax] [mm] = | D25: 9000 | E25: 9000 | F25: 9000 | G25: 9000 | H25: 9000 | I25: 9000 | J25: 9000 | K25: 9000 | L25: 9000 | M25: 9000 | N25: 9000 | O25: 9000 | P25: 9000 | Q25: 9000 | R25: 9000 | S25: 9000 | T25: 9000 | U25: 9000 | V25: 9000 | W25: 9000 | X25: 9000 | Y25: 9000
A26: Inclinazione dell'anima [° | rad] = | D26: 0 | E26: 0 | F26: 0 | G26: 0 | H26: 0 | I26: 0 | J26: 0 | K26: 0 | L26: 0 | M26: 0 | N26: 0 | O26: 0 | P26: 0 | Q26: 0 | R26: 0 | S26: 0 | T26: 0 | U26: 0 | V26: 0 | W26: 0 | X26: 0 | Y26: 0
A27: Interasse inferiore fra le travi hmin | hmax [mm] = | D27: 9000 | E27: 9000 | F27: 9000 | G27: 9000 | H27: 9000 | I27: 9000 | J27: 9000 | K27: 9000 | L27: 9000 | M27: 9000 | N27: 9000 | O27: 9000 | P27: 9000 | Q27: 9000 | R27: 9000 | S27: 9000 | T27: 9000 | U27: 9000 | V27: 9000 | W27: 9000 | X27: 9000 | Y27: 9000
A28: Lunghezza concio [mm] = | D28: 7000 | F28: 11000 | H28: 10000 | J28: 5500 | L28: 10000 | N28: 7500 | P28: 7500 | R28: 10000 | T28: 7500 | V28: 7500 | X28: 10000
A29: Altezza media della trave [mm] = | D29: 2200 | F29: 2200 | H29: 2200 | J29: 2200 | L29: 2200 | N29: 2200 | P29: 2200 | R29: 2200 | T29: 2200 | V29: 2200 | X29: 2200
A30: Altezza minima della trave h1 [mm] = | D30: 2200 | F30: 2200 | H30: 2200 | J30: 2200 | L30: 2200 | N30: 2200 | P30: 2200 | R30: 2200 | T30: 2200 | V30: 2200 | X30: 2200
A31: Altezza massima della trave h2 [mm] = | D31: 2200 | F31: 2200 | H31: 2200 | J31: 2200 | L31: 2200 | N31: 2200 | P31: 2200 | R31: 2200 | T31: 2200 | V31: 2200 | X31: 2200
C32: area [mm2] = | D32: 93120 | F32: 108096 | H32: 116520 | J32: 135400 | L32: 216960 | N32: 146160 | P32: 116520 | R32: 108096 | T32: 111840 | V32: 138400 | X32: 216960
C33: peso concio [kg | kg/m] = | D33: 5116.944 | E33: 730.992 | F33: 9334.0896 | G33: 848.5536 | H33: 9146.82 | I33: 914.682 | J33: 5845.895 | K33: 1062.89 | L33: 17031.36 | M33: 1703.136 | N33: 8605.17 | O33: 1147.356 | P33: 6860.115 | Q33: 914.682 | R33: 8485.536 | S33: 848.5536 | T33: 6584.58 | U33: 877.944 | V33: 8148.3 | W33: 1086.44 | X33: 17031.36 | Y33: 1703.136
A34: Larghezza e spessore pb superiore esterna [mm] = | D34: 600 | E34: 24 | F34: 600 | G34: 24 | H34: 600 | I34: 24 | J34: 700 | K34: 30 | L34: 900 | M34: 40 | N34: 800 | O34: 40 | P34: 600 | Q34: 24 | R34: 600 | S34: 24 | T34: 600 | U34: 24 | V34: 800 | W34: 30 | X34: 900 | Y34: 40
A35: Larghezza e spessore pb superiore interna [mm] = | L35: 800 | M35: 40 | X35: 800 | Y35: 40
A36: Spessore e altezza anima [mm] = | D36: 20 | E36: 2136 | F36: 16 | G36: 2106 | H36: 20 | I36: 2106 | J36: 24 | K36: 2100 | L36: 24 | M36: 2040 | N36: 24 | O36: 2090 | P36: 20 | Q36: 2106 | R36: 16 | S36: 2106 | T36: 20 | U36: 2112 | V36: 24 | W36: 2100 | X36: 24 | Y36: 2040
A37: Larghezza e spessore pb inferiore interna [mm] = | F37: 800 | G37: 30 | H37: 800 | I37: 30 | J37: 800 | K37: 30 | L37: 1200 | M37: 40 | N37: 800 | O37: 30 | P37: 800 | Q37: 30 | R37: 800 | S37: 30 | T37: 800 | U37: 24 | V37: 800 | W37: 30 | X37: 1200 | Y37: 40
A38: Larghezza e spessore pb inferiore esterna [mm] = | D38: 900 | E38: 40 | F38: 900 | G38: 40 | H38: 900 | I38: 40 | J38: 1000 | K38: 40 | L38: 1300 | M38: 40 | N38: 1000 | O38: 40 | P38: 900 | Q38: 40 | R38: 900 | S38: 40 | T38: 900 | U38: 40 | V38: 1000 | W38: 40 | X38: 1300 | Y38: 40
A39: Concio fessurato / non fessurato [hmin | hmax] = | D39: NF | E39: NF | F39: NF | G39: NF | H39: NF | I39: NF | J39: NF | K39: F | L39: NF | M39: F | N39: NF | O39: F | P39: NF | Q39: NF | R39: NF | S39: NF | T39: NF | U39: NF | V39: NF | W39: F | X39: NF | Y39: F
A40: Stato prevalente soletta | D40: compressa | F40: compressa | H40: compressa | J40: tesa | L40: tesa | N40: tesa | P40: compressa | R40: compressa | T40: compressa | V40: tesa | X40: tesa
A41: Warning = | F41: Efficacia pb inf 100% | H41: Efficacia pb inf 100% | J41: Efficacia pb inf 100% | L41: Efficacia pb inf 100% | N41: Efficacia pb inf 100% | P41: Efficacia pb inf 100% | R41: Efficacia pb inf 100% | T41: Efficacia pb inf 99% | V41: Efficacia pb inf 100% | X41: Efficacia pb inf 100%
...

Sheet Gaudicose
A1: COMMESSA: | B1: 215_ALFONSINE
A2: OPERA D'ARTE: | B2: VIADOTTO DI APPROCCIO EST
A3: Data: | B3: 45128
A4: File Midas: | B4: 02_Alfonsine_Viadotto est
A5: File SuperFoglio: | B5: 05_Alfonsine_Viadotto_EST_SPF
D7: Spalla | L7: Pila | X7: Pila
A8: concio : | D8: 1 | F8: 2 | H8: 3 | J8: 4 | L8: 5 | N8: 6 | P8: 7 | R8: 8 | T8: 9 | V8: 10 | X8: 11
A9: Giunzione bullonata o saldata? (B/S) [hmin | hmax]= | D9: S | E9: S | F9: S | G9: S | H9: S | I9: S | J9: S | K9: S | L9: S | M9: S | N9: S | O9: S | P9: S | Q9: S | R9: S | S9: S | T9: S | U9: S | V9: S | W9: S | X9: S | Y9: S
A10: Armatura longitudinale superiore al metro trasversale [n | Φ /m] = | D10: 5 | E10: 26 | F10: 5 | G10: 20 | H10: 5 | I10: 20 | J10: 10 | K10: 26 | L10: 10 | M10: 26 | N10: 10 | O10: 26 | P10: 10 | Q10: 22 | R10: 10 | S10: 16 | T10: 10 | U10: 22 | V10: 10 | W10: 26 | X10: 10 | Y10: 26
A11: Armatura longitudinale superiore al metro trasversale [mm2/m] = | D11: 2654.6458 | F11: 1570.7963 | H11: 1570.7963 | J11: 5309.2916 | L11: 5309.2916 | N11: 5309.2916 | P11: 3801.3271 | R11: 2010.6193 | T11: 3801.3271 | V11: 5309.2916 | X11: 5309.2916
A12: Distanza dall'estradosso soletta - arm.superiore [mm] = | D12: 50 | F12: 50 | H12: 50 | J12: 50 | L12: 50 | N12: 50 | P12: 50 | R12: 50 | T12: 50 | V12: 50 | X12: 50
A13: Armatura longitudinale inferiore al metro trasversale [n | Φ /m] = | J13: 10 | K13: 26 | L13: 10 | M13: 26 | N13: 10 | O13: 26 | V13: 10 | W13: 26 | X13: 10 | Y13: 26
A14: Armatura longitudinale inferiore al metro trasversale [mm2/m] = | D14: 0 | F14: 0 | H14: 0 | J14: 5309.2916 | L14: 5309.2916 | N14: 5309.2916 | P14: 0 | R14: 0 | T14: 0 | V14: 5309.2916 | X14: 5309.2916
A15: Distanza dall'estradosso soletta - arm.inferiore [mm] = | D15: 289 | F15: 289 | H15: 289 | J15: 270 | L15: 270 | N15: 270 | P15: 289 | R15: 289 | T15: 289 | V15: 270 | X15: 270
A16: Area della diagonale inferiore di controvento [mm2] = | D16: 0 | F16: 0 | H16: 0 | J16: 0 | L16: 0 | N16: 0 | P16: 0 | R16: 0 | T16: 0 | V16: 0 | X16: 0
C17: n° di diagonali in una maglia = | D17: 0 | F17: 0 | H17: 0 | J17: 0 | L17: 0 | N17: 0 | P17: 0 | R17: 0 | T17: 0 | V17: 0 | X17: 0
A18: Larghezza soletta [mm] = | D18: 14300 | F18: 14300 | H18: 14300 | J18: 14300 | L18: 14300 | N18: 14300 | P18: 14300 | R18: 14300 | T18: 14300 | V18: 14300 | X18: 14300
A19: Sbalzo soletta lato di verifica [mm] = | D19: 2650 | F19: 2650 | H19: 2650 | J19: 2650 | L19: 2650 | N19: 2650 | P19: 2650 | R19: 2650 | T19: 2650 | V19: 2650 | X19: 2650
A20: Riduzione soletta collaborante [sbalzo | interno ] [mm] = | D20: 0 | E20: 0 | F20: 0 | G20: 0 | H20: 0 | I20: 0 | J20: 0 | K20: 0 | L20: 0 | M20: 0 | N20: 0 | O20: 0 | P20: 0 | Q20: 0 | R20: 0 | S20: 0 | T20: 0 | U20: 0 | V20: 0 | W20: 0 | X20: 0 | Y20: 0
A21: LAMIERE
C22: Rapporto limite per il web breathing | rapporto bw/tw | D22: 184 | E22: 106.8 | F22: 184 | G22: 131.625 | H22: 184 | I22: 105.3 | J22: 184 | K22: 87.5 | L22: 184 | M22: 85 | N22: 230 | O22: 86.666667 | P22: 230 | Q22: 105.3 | R22: 230 | S22: 131.625 | T22: 230 | U22: 105.6 | V22: 230 | W22: 87.5 | X22: 230 | Y22: 85
A23: concio : | D23: 1 | F23: 2 | H23: 3 | J23: 4 | L23: 5 | N23: 6 | P23: 7 | R23: 8 | T23: 9 | V23: 10 | X23: 11
A24: Lunghezza della travata [mm] = | D24: 38500 | F24: 38500 | H24: 38500 | J24: 38500 | L24: 38500 | N24: 50000 | P24: 50000 | R24: 50000 | T24: 50000 | V24: 50000 | X24: 50000
A25: Interasse superiore fra le travi [hmin | hmax] [mm] = | D25: 9000 | E25: 9000 | F25: 9000 | G25: 9000 | H25: 9000 | I25: 9000 | J25: 9000 | K25: 9000 | L25: 9000 | M25: 9000 | N25: 9000 | O25: 9000 | P25: 9000 | Q25: 9000 | R25: 9000 | S25: 9000 | T25: 9000 | U25: 9000 | V25: 9000 | W25: 9000 | X25: 9000 | Y25: 9000
A26: Inclinazione dell'anima [° | rad] = | D26: 0 | E26: 0 | F26: 0 | G26: 0 | H26: 0 | I26: 0 | J26: 0 | K26: 0 | L26: 0 | M26: 0 | N26: 0 | O26: 0 | P26: 0 | Q26: 0 | R26: 0 | S26: 0 | T26: 0 | U26: 0 | V26: 0 | W26: 0 | X26: 0 | Y26: 0
A27: Interasse inferiore fra le travi hmin | hmax [mm] = | D27: 9000 | E27: 9000 | F27: 9000 | G27: 9000 | H27: 9000 | I27: 9000 | J27: 9000 | K27: 9000 | L27: 9000 | M27: 9000 | N27: 9000 | O27: 9000 | P27: 9000 | Q27: 9000 | R27: 9000 | S27: 9000 | T27: 9000 | U27: 9000 | V27: 9000 | W27: 9000 | X27: 9000 | Y27: 9000
A28: Lunghezza concio [mm] = | D28: 7000 | F28: 11000 | H28: 10000 | J28: 5500 | L28: 10000 | N28: 7500 | P28: 7500 | R28: 10000 | T28: 7500 | V28: 7500 | X28: 10000
A29: Altezza media della trave [mm] = | D29: 2200 | F29: 2200 | H29: 2200 | J29: 2200 | L29: 2200 | N29: 2200 | P29: 2200 | R29: 2200 | T29: 2200 | V29: 2200 | X29: 2200
A30: Altezza minima della trave h1 [mm] = | D30: 2200 | F30: 2200 | H30: 2200 | J30: 2200 | L30: 2200 | N30: 2200 | P30: 2200 | R30: 2200 | T30: 2200 | V30: 2200 | X30: 2200
A31: Altezza massima della trave h2 [mm] = | D31: 2200 | F31: 2200 | H31: 2200 | J31: 2200 | L31: 2200 | N31: 2200 | P31: 2200 | R31: 2200 | T31: 2200 | V31: 2200 | X31: 2200
C32: area [mm2] = | D32: 93120 | F32: 108096 | H32: 116520 | J32: 135400 | L32: 216960 | N32: 146160 | P32: 116520 | R32: 108096 | T32: 111840 | V32: 138400 | X32: 216960
C33: peso concio [kg | kg/m] = | D33: 5116.944 | E33: 730.992 | F33: 9334.0896 | G33: 848.5536 | H33: 9146.82 | I33: 914.682 | J33: 5845.895 | K33: 1062.89 | L33: 17031.36 | M33: 1703.136 | N33: 8605.17 | O33: 1147.356 | P33: 6860.115 | Q33: 914.682 | R33: 8485.536 | S33: 848.5536 | T33: 6584.58 | U33: 877.944 | V33: 8148.3 | W33: 1086.44 | X33: 17031.36 | Y33: 1703.136
A34: Larghezza e spessore pb superiore esterna [mm] = | D34: 600 | E34: 24 | F34: 600 | G34: 24 | H34: 600 | I34: 24 | J34: 700 | K34: 30 | L34: 900 | M34: 40 | N34: 800 | O34: 40 | P34: 600 | Q34: 24 | R34: 600 | S34: 24 | T34: 600 | U34: 24 | V34: 800 | W34: 30 | X34: 900 | Y34: 40
A35: Larghezza e spessore pb superiore interna [mm] = | L35: 800 | M35: 40 | X35: 800 | Y35: 40
A36: Spessore e altezza anima [mm] = | D36: 20 | E36: 2136 | F36: 16 | G36: 2106 | H36: 20 | I36: 2106 | J36: 24 | K36: 2100 | L36: 24 | M36: 2040 | N36: 24 | O36: 2090 | P36: 20 | Q36: 2106 | R36: 16 | S36: 2106 | T36: 20 | U36: 2112 | V36: 24 | W36: 2100 | X36: 24 | Y36: 2040
A37: Larghezza e spessore pb inferiore interna [mm] = | F37: 800 | G37: 30 | H37: 800 | I37: 30 | J37: 800 | K37: 30 | L37: 1200 | M37: 40 | N37: 800 | O37: 30 | P37: 800 | Q37: 30 | R37: 800 | S37: 30 | T37: 800 | U37: 24 | V37: 800 | W37: 30 | X37: 1200 | Y37: 40
A38: Larghezza e spessore pb inferiore esterna [mm] = | D38: 900 | E38: 40 | F38: 900 | G38: 40 | H38: 900 | I38: 40 | J38: 1000 | K38: 40 | L38: 1300 | M38: 40 | N38: 1000 | O38: 40 | P38: 900 | Q38: 40 | R38: 900 | S38: 40 | T38: 900 | U38: 40 | V38: 1000 | W38: 40 | X38: 1300 | Y38: 40
A39: Concio fessurato / non fessurato [hmin | hmax] = | D39: NF | E39: NF | F39: NF | G39: NF | H39: NF | I39: NF | J39: NF | K39: F | L39: NF | M39: F | N39: NF | O39: F | P39: NF | Q39: NF | R39: NF | S39: NF | T39: NF | U39: NF | V39: NF | W39: F | X39: NF | Y39: F
A40: Stato prevalente soletta | D40: compressa | F40: compressa | H40: compressa | J40: tesa | L40: tesa | N40: tesa | P40: compressa | R40: compressa | T40: compressa | V40: tesa | X40: tesa
A41: Warning = | F41: Efficacia pb inf 100% | H41: Efficacia pb inf 100% | J41: Efficacia pb inf 100% | L41: Efficacia pb inf 100% | N41: Efficacia pb inf 100% | P41: Efficacia pb inf 100% | R41: Efficacia pb inf 100% | T41: Efficacia pb inf 99% | V41: Efficacia pb inf 100% | X41: Efficacia pb inf 100%
...

Sheet Delta
A1: COMMESSA: | B1: 215_ALFONSINE
A2: OPERA D'ARTE: | B2: VIADOTTO DI APPROCCIO EST
A3: Data: | B3: 45128
A4: File Midas: | B4: 02_Alfonsine_Viadotto est
A5: File SuperFoglio: | B5: 05_Alfonsine_Viadotto_EST_SPF
D7: Spalla | L7: Pila | X7: Pila
A8: concio : | D8: 1 | F8: 2 | H8: 3 | J8: 4 | L8: 5 | N8: 6 | P8: 7 | R8: 8 | T8: 9 | V8: 10 | X8: 11
A9: Giunzione bullonata o saldata? (B/S) [hmin | hmax]= | D9: S | E9: S | F9: S | G9: S | H9: S | I9: S | J9: S | K9: S | L9: S | M9: S | N9: S | O9: S | P9: S | Q9: S | R9: S | S9: S | T9: S | U9: S | V9: S | W9: S | X9: S | Y9: S
A10: Armatura longitudinale superiore al metro trasversale [n | Φ /m] = | D10: 5 | E10: 26 | F10: 5 | G10: 20 | H10: 5 | I10: 20 | J10: 10 | K10: 26 | L10: 10 | M10: 26 | N10: 10 | O10: 26 | P10: 10 | Q10: 22 | R10: 10 | S10: 16 | T10: 10 | U10: 22 | V10: 10 | W10: 26 | X10: 10 | Y10: 26
A11: Armatura longitudinale superiore al metro trasversale [mm2/m] = | D11: 2654.6458 | F11: 1570.7963 | H11: 1570.7963 | J11: 5309.2916 | L11: 5309.2916 | N11: 5309.2916 | P11: 3801.3271 | R11: 2010.6193 | T11: 3801.3271 | V11: 5309.2916 | X11: 5309.2916
A12: Distanza dall'estradosso soletta - arm.superiore [mm] = | D12: 50 | F12: 50 | H12: 50 | J12: 50 | L12: 50 | N12: 50 | P12: 50 | R12: 50 | T12: 50 | V12: 50 | X12: 50
A13: Armatura longitudinale inferiore al metro trasversale [n | Φ /m] = | J13: 10 | K13: 26 | L13: 10 | M13: 26 | N13: 10 | O13: 26 | V13: 10 | W13: 26 | X13: 10 | Y13: 26
A14: Armatura longitudinale inferiore al metro trasversale [mm2/m] = | D14: 0 | F14: 0 | H14: 0 | J14: 5309.2916 | L14: 5309.2916 | N14: 5309.2916 | P14: 0 | R14: 0 | T14: 0 | V14: 5309.2916 | X14: 5309.2916
A15: Distanza dall'estradosso soletta - arm.inferiore [mm] = | D15: 289 | F15: 289 | H15: 289 | J15: 270 | L15: 270 | N15: 270 | P15: 289 | R15: 289 | T15: 289 | V15: 270 | X15: 270
A16: Area della diagonale inferiore di controvento [mm2] = | D16: 0 | F16: 0 | H16: 0 | J16: 0 | L16: 0 | N16: 0 | P16: 0 | R16: 0 | T16: 0 | V16: 0 | X16: 0
C17: n° di diagonali in una maglia = | D17: 0 | F17: 0 | H17: 0 | J17: 0 | L17: 0 | N17: 0 | P17: 0 | R17: 0 | T17: 0 | V17: 0 | X17: 0
A18: Larghezza soletta [mm] = | D18: 14300 | F18: 14300 | H18: 14300 | J18: 14300 | L18: 14300 | N18: 14300 | P18: 14300 | R18: 14300 | T18: 14300 | V18: 14300 | X18: 14300
A19: Sbalzo soletta lato di verifica [mm] = | D19: 2650 | F19: 2650 | H19: 2650 | J19: 2650 | L19: 2650 | N19: 2650 | P19: 2650 | R19: 2650 | T19: 2650 | V19: 2650 | X19: 2650
A20: Riduzione soletta collaborante [sbalzo | interno ] [mm] = | D20: 0 | E20: 0 | F20: 0 | G20: 0 | H20: 0 | I20: 0 | J20: 0 | K20: 0 | L20: 0 | M20: 0 | N20: 0 | O20: 0 | P20: 0 | Q20: 0 | R20: 0 | S20: 0 | T20: 0 | U20: 0 | V20: 0 | W20: 0 | X20: 0 | Y20: 0
A21: LAMIERE
C22: Rapporto limite per il web breathing | rapporto bw/tw | D22: 184 | E22: 106.8 | F22: 184 | G22: 131.625 | H22: 184 | I22: 105.3 | J22: 184 | K22: 87.5 | L22: 184 | M22: 85 | N22: 230 | O22: 86.666667 | P22: 230 | Q22: 105.3 | R22: 230 | S22: 131.625 | T22: 230 | U22: 105.6 | V22: 230 | W22: 87.5 | X22: 230 | Y22: 85
A23: concio : | D23: 1 | F23: 2 | H23: 3 | J23: 4 | L23: 5 | N23: 6 | P23: 7 | R23: 8 | T23: 9 | V23: 10 | X23: 11
A24: Lunghezza della travata [mm] = | D24: 38500 | F24: 38500 | H24: 38500 | J24: 38500 | L24: 38500 | N24: 50000 | P24: 50000 | R24: 50000 | T24: 50000 | V24: 50000 | X24: 50000
A25: Interasse superiore fra le travi [hmin | hmax] [mm] = | D25: 9000 | E25: 9000 | F25: 9000 | G25: 9000 | H25: 9000 | I25: 9000 | J25: 9000 | K25: 9000 | L25: 9000 | M25: 9000 | N25: 9000 | O25: 9000 | P25: 9000 | Q25: 9000 | R25: 9000 | S25: 9000 | T25: 9000 | U25: 9000 | V25: 9000 | W25: 9000 | X25: 9000 | Y25: 9000
A26: Inclinazione dell'anima [° | rad] = | D26: 0 | E26: 0 | F26: 0 | G26: 0 | H26: 0 | I26: 0 | J26: 0 | K26: 0 | L26: 0 | M26: 0 | N26: 0 | O26: 0 | P26: 0 | Q26: 0 | R26: 0 | S26: 0 | T26: 0 | U26: 0 | V26: 0 | W26: 0 | X26: 0 | Y26: 0
A27: Interasse inferiore fra le travi hmin | hmax [mm] = | D27: 9000 | E27: 9000 | F27: 9000 | G27: 9000 | H27: 9000 | I27: 9000 | J27: 9000 | K27: 9000 | L27: 9000 | M27: 9000 | N27: 9000 | O27: 9000 | P27: 9000 | Q27: 9000 | R27: 9000 | S27: 9000 | T27: 9000 | U27: 9000 | V27: 9000 | W27: 9000 | X27: 9000 | Y27: 9000
A28: Lunghezza concio [mm] = | D28: 7000 | F28: 11000 | H28: 10000 | J28: 5500 | L28: 10000 | N28: 7500 | P28: 7500 | R28: 10000 | T28: 7500 | V28: 7500 | X28: 10000
A29: Altezza media della trave [mm] = | D29: 2200 | F29: 2200 | H29: 2200 | J29: 2200 | L29: 2200 | N29: 2200 | P29: 2200 | R29: 2200 | T29: 2200 | V29: 2200 | X29: 2200
A30: Altezza minima della trave h1 [mm] = | D30: 2200 | F30: 2200 | H30: 2200 | J30: 2200 | L30: 2200 | N30: 2200 | P30: 2200 | R30: 2200 | T30: 2200 | V30: 2200 | X30: 2200
A31: Altezza massima della trave h2 [mm] = | D31: 2200 | F31: 2200 | H31: 2200 | J31: 2200 | L31: 2200 | N31: 2200 | P31: 2200 | R31: 2200 | T31: 2200 | V31: 2200 | X31: 2200
C32: area [mm2] = | D32: 93120 | F32: 108096 | H32: 116520 | J32: 135400 | L32: 216960 | N32: 146160 | P32: 116520 | R32: 108096 | T32: 111840 | V32: 138400 | X32: 216960
C33: peso concio [kg | kg/m] = | D33: 5116.944 | E33: 730.992 | F33: 9334.0896 | G33: 848.5536 | H33: 9146.82 | I33: 914.682 | J33: 5845.895 | K33: 1062.89 | L33: 17031.36 | M33: 1703.136 | N33: 8605.17 | O33: 1147.356 | P33: 6860.115 | Q33: 914.682 | R33: 8485.536 | S33: 848.5536 | T33: 6584.58 | U33: 877.944 | V33: 8148.3 | W33: 1086.44 | X33: 17031.36 | Y33: 1703.136
A34: Larghezza e spessore pb superiore esterna [mm] = | D34: 600 | E34: 24 | F34: 600 | G34: 24 | H34: 600 | I34: 24 | J34: 700 | K34: 30 | L34: 900 | M34: 40 | N34: 800 | O34: 40 | P34: 600 | Q34: 24 | R34: 600 | S34: 24 | T34: 600 | U34: 24 | V34: 800 | W34: 30 | X34: 900 | Y34: 40
A35: Larghezza e spessore pb superiore interna [mm] = | L35: 800 | M35: 40 | X35: 800 | Y35: 40
A36: Spessore e altezza anima [mm] = | D36: 20 | E36: 2136 | F36: 16 | G36: 2106 | H36: 20 | I36: 2106 | J36: 24 | K36: 2100 | L36: 24 | M36: 2040 | N36: 24 | O36: 2090 | P36: 20 | Q36: 2106 | R36: 16 | S36: 2106 | T36: 20 | U36: 2112 | V36: 24 | W36: 2100 | X36: 24 | Y36: 2040
A37: Larghezza e spessore pb inferiore interna [mm] = | F37: 800 | G37: 30 | H37: 800 | I37: 30 | J37: 800 | K37: 30 | L37: 1200 | M37: 40 | N37: 800 | O37: 30 | P37: 800 | Q37: 30 | R37: 800 | S37: 30 | T37: 800 | U37: 24 | V37: 800 | W37: 30 | X37: 1200 | Y37: 40
A38: Larghezza e spessore pb inferiore esterna [mm] = | D38: 900 | E38: 40 | F38: 900 | G38: 40 | H38: 900 | I38: 40 | J38: 1000 | K38: 40 | L38: 1300 | M38: 40 | N38: 1000 | O38: 40 | P38: 900 | Q38: 40 | R38: 900 | S38: 40 | T38: 900 | U38: 40 | V38: 1000 | W38: 40 | X38: 1300 | Y38: 40
A39: Concio fessurato / non fessurato [hmin | hmax] = | D39: NF | E39: NF | F39: NF | G39: NF | H39: NF | I39: NF | J39: NF | K39: F | L39: NF | M39: F | N39: NF | O39: F | P39: NF | Q39: NF | R39: NF | S39: NF | T39: NF | U39: NF | V39: NF | W39: F | X39: NF | Y39: F
A40: Stato prevalente soletta | D40: compressa | F40: compressa | H40: compressa | J40: tesa | L40: tesa | N40: tesa | P40: compressa | R40: compressa | T40: compressa | V40: tesa | X40: tesa
A41: Warning = | F41: Efficacia pb inf 100% | H41: Efficacia pb inf 100% | J41: Efficacia pb inf 100% | L41: Efficacia pb inf 100% | N41: Efficacia pb inf 100% | P41: Efficacia pb inf 100% | R41: Efficacia pb inf 100% | T41: Efficacia pb inf 99% | V41: Efficacia pb inf 100% | X41: Efficacia pb inf 100%
...
